Workbook
Name Scenario: 'FE Assumptions'!#REF!
Name quantityDemanded: #REF!
Name demandSlope: #REF!
Name Scenario: #REF!
Name demandIntercept: #REF!
Name marketSize: #REF!

Sheet Index
B15: INDEX
B17: FINANCE | E17: MARKETING | H17: OPERATIONS
B18: FE ASSUMPTIONS | E18: MK ASSUMPTIONS | H18: OM ASSUMPTIONS
B19: FE STARTING DATA SET | E19: MK ACV DISTRIBUTION | H19: OM COST ANALYSIS
B20: FE INCOME STATEMENT | E20: MK DEMAND CURVE & PURCHASE INTENT | H20: OM CAPITAL EXPENDITURES
B21: FE BALANCE SHEET | E21: MK WEIGHTED PRICE CALCULATIONS | H21: OM INFORMATION SYSTEMS EXPENSES
B22: FE COMPARABLE COMPANIES ANALYSIS | E22: MK SALES PROJECTIONS | H22: OM DIRECT MATERIALS & DIRECT LABOR
B23: FE CASH FLOW | E23: MK IMC SCHEDULE | H23: OM INVENTORY
H24: OM DEMAND AND LEAD TIME
H25: OM G&A EXPENSES
H26: OM PROCESS FLOW
H27: OM CAPACITY ANALYSIS
H28: OM G&A EXPENSES
H29: OM MOH EXPENSES
H30: OM LOCATION ANALYSIS
H31: OM STARTUP COSTS

Sheet FE Assumptions
A1: ASSUMPTIONS
A2: IN US DOLLARS ($) | B2: START-UP | C2: YEAR 1 | D2: YEAR 2 | E2: YEAR 3 | F2: YEAR 4 | G2: YEAR 5 | I2: Link To
A5: INITIAL STARTUP COSTS (START-UP COLUMN ONLY)
A7: INITIAL INVESTMENT IN FIXED ASSETS
A8: Long Term Balance Sheet Items (Can be depreciated - includes IS equip & Factory/office buildout costs) | B8: ='OM Capital Expenditures'!D49+'OM IS Expenses'!C33+'OM Startup Costs'!C18 -> 263922.25 | I8: OM
A10: INITIAL INVESTMENT IN NET WORKING CAPITAL
A11: Cash (Additional Cash required in addition to Start Up costs) | B11: 0 | I11: FE
A12: Raw Materials & Work in Process, Start-Up Period Only (Put Years 1-5 in table Below) | B12: ='OM Startup Costs'!C29+'OM Startup Costs'!C30 -> 30321.778 | I12: OM
A13: Finished Goods Start-up Period Only (Put Years 1-5 in table Below) | B13: ='OM Startup Costs'!C31 -> 2341.5562 | I13: OM
A15: INITIAL OPERATING EXPENSES
A16: Product Development (Prototype, engineer, etc.) | B16: ='OM Startup Costs'!C12 -> 55000 | I16: OM
A17: Pre-Marketing Expenses (Marketing expenses before Year 1) See Sales Projection Tutorial | B17: ='MK IMC Schedule'!O7 -> 40242.05 | I17: MK
A18: All Other (Miscellaneous non depreciated expenses, additional salaries, Rent etc.) | B18: ='OM Startup Costs'!C25 -> 42362.288 | I18: MK, OM
A19: Subtotal Start Up Operating Expenses | B19: =SUM(B16:B18) -> 137604.34
A21: OPERATING INFORMATION (YEARS 1-5)
A23: UNITS SOLD
A24: Units into independent retailers | C24: ='MK ACV Distribution'!C8 -> 40473.718 | D24: ='MK ACV Distribution'!C15 -> 57320.774 | E24: ='MK ACV Distribution'!C22 -> 57689.2 | F24: ='MK ACV Distribution'!C29 -> 70876.639 | G24: ='MK ACV Distribution'!C36 -> 86809.709 | I24: MK
A25: Units online | C25: ='MK ACV Distribution'!D8 -> 6745.6196 | D25: ='MK ACV Distribution'!D15 -> 23883.656 | E25: ='MK ACV Distribution'!D22 -> 38459.467 | F25: ='MK ACV Distribution'!D29 -> 47251.093 | G25: ='MK ACV Distribution'!D36 -> 65107.282 | I25: MK
A26: Units into chain retailer | E26: ='MK ACV Distribution'!E22 -> 9614.8667 | F26: ='MK ACV Distribution'!E29 -> 23625.546 | G26: ='MK ACV Distribution'!E36 -> 57873.139 | I26: MK
A27: Units into mass merchants | F27: ='MK ACV Distribution'!F29 -> 17719.16 | G27: ='MK ACV Distribution'!F36 -> 28936.57 | I27: MK
A28: TOTAL UNITS SOLD | C28: =SUM(C24:C27) -> 47219.337 | D28: =SUM(D24:D27) -> 81204.43 | E28: =SUM(E24:E27) -> 105763.53 | F28: =SUM(F24:F27) -> 159472.44 | G28: =SUM(G24:G27) -> 238726.7
A30: WEIGHTED AVERAGE MANUFACTURER SELLING PRICE
A31: To independent retailers | C31: ='MK Weighted Price Calculations'!D7 -> 31.5 | D31: ='MK Weighted Price Calculations'!D16 -> 31.5 | E31: ='MK Weighted Price Calculations'!D25 -> 31.5 | F31: ='MK Weighted Price Calculations'!D34 -> 31.5 | G31: ='MK Weighted Price Calculations'!D43 -> 31.5 | I31: MK
A32: For online sales | C32: ='MK Weighted Price Calculations'!D6 -> 35 | D32: ='MK Weighted Price Calculations'!D15 -> 35 | E32: ='MK Weighted Price Calculations'!D24 -> 35 | F32: ='MK Weighted Price Calculations'!D33 -> 35 | G32: ='MK Weighted Price Calculations'!D42 -> 35 | I32: MK
A33: To chain retailer | C33: 0 | D33: 0 | E33: ='MK Weighted Price Calculations'!D26 -> 28.35 | F33: ='MK Weighted Price Calculations'!D35 -> 28.35 | G33: ='MK Weighted Price Calculations'!D44 -> 28.35 | I33: MK
A34: To mass merchants | C34: 0 | D34: 0 | E34: 0 | F34: ='MK Weighted Price Calculations'!D36 -> 22.68 | G34: ='MK Weighted Price Calculations'!D45 -> 22.68 | I34: MK
A35: AVERAGE WEIGHTED MANUFACTURER'S AVERAGE SELLING PRICE TO CHANNEL | C35: ='MK Weighted Price Calculations'!C10 -> 34.5 | D35: ='MK Weighted Price Calculations'!C19 -> 33.970588 | E35: ='MK Weighted Price Calculations'!C28 -> 33.122727 | F35: ='MK Weighted Price Calculations'!C37 -> 31.608889 | G35: ='MK Weighted Price Calculations'!C46 -> 30.94
A37: COST OF GOODS SOLD
A38: Variable Cost Per Unit ($/Unit) (Total Direct Cost = Direct Labor + Direct Materials ) | C38: ='OM Direct Materials & Direct La'!D14+('OM Direct Materials & Direct La'!F33+'OM Direct Materials & Direct La'!F34) -> 10.187934 | D38: ='OM Direct Materials & Direct La'!E14+'OM Direct Materials & Direct La'!F51+'OM Direct Materials & Direct La'!F52 -> 10.324093 | E38: ='OM Direct Materials & Direct La'!F14+'OM Direct Materials & Direct La'!F68+'OM Direct Materials & Direct La'!F69 -> 10.708818 | F38: ='OM Direct Materials & Direct La'!G14+'OM Direct Materials & Direct La'!F85+'OM Direct Materials & Direct La'!F86 -> 10.104934 | G38: ='OM Direct Materials & Direct La'!H14+'OM Direct Materials & Direct La'!F102+'OM Direct Materials & Direct La'!F103 -> 10.035576 | I38: OM
A39: Total Outbound Freight ($) (The gross amount, Not Per Unit) | C39: ='OM Location Analysis '!C64 -> 7254.9139 | D39: ='OM Location Analysis '!D64 -> 15413.413 | E39: ='OM Location Analysis '!E64 -> 22117.312 | F39: ='OM Location Analysis '!F64 -> 31571.436 | G39: ='OM Location Analysis '!G64 -> 46900.59 | I39: OM
A40: Total Variable Costs Including Freight ($) | C40: =(C38*C28)+C39 -> 488322.42 | D40: =(D38*D28)+D39 -> 853775.5 | E40: =(E38*E28)+E39 -> 1154719.8 | F40: =(F38*F28)+F39 -> 1643029.9 | G40: =(G38*G28)+G39 -> 2442660.6
A41: Fixed Production Costs ($) (Total MOH per year) | C41: ='OM MOH Expenses'!C15 -> 192923.91 | D41: ='OM MOH Expenses'!D15 -> 248628.14 | E41: ='OM MOH Expenses'!E15 -> 290008.74 | F41: ='OM MOH Expenses'!F15 -> 376145.86 | G41: ='OM MOH Expenses'!G15 -> 501523.09 | I41: OM | K41: COGS Sensitivity
A42: Total Cost of Goods Sold | C42: =C40+C41 -> 681246.33 | D42: =D40+D41 -> 1102403.6 | E42: =E40+E41 -> 1444728.5 | F42: =F40+F41 -> 2019175.7 | G42: =G40+G41 -> 2944183.6 | K42: 1
A43: Per Unit | C43: =C42/C28 -> 14.427274 | D43: =D42/D28 -> 13.575659 | E43: =E42/E28 -> 13.659987 | F43: =F42/F28 -> 12.661597 | G43: =G42/G28 -> 12.332863
A45: SELLING, GENERAL, AND ADMINISTRATIVE EXPENSES
A46: Production costs not included in Cost of Good sold (if any, you may not have any) | I46: OM
A47: Fixed Administrative Costs | C47: ='OM G&A Expenses'!F18 -> 628381.34 | D47: ='OM G&A Expenses'!F39 -> 668845.24 | E47: ='OM G&A Expenses'!F62 -> 849961.52 | F47: ='OM G&A Expenses'!F86 -> 1026543.7 | G47: ='OM G&A Expenses'!F113 -> 1381304.5 | I47: OM
A48: Marketing Expenses (Push and Pull) Excluding Manufacturers Reps ($) | C48: ='MK IMC Schedule'!O31 -> 268280.33 | D48: ='MK IMC Schedule'!O55 -> 344232.76 | E48: ='MK IMC Schedule'!O79 -> 396844.43 | F48: ='MK IMC Schedule'!O103 -> 503401.33 | G48: ='MK IMC Schedule'!O127 -> 631633 | I48: MK
A49: Manufacturer's Sales Reps Commission Expense (10% - excludes Online Units) | C49: =C24*C35*'Starting Data Set'!D22 -> 139634.33 | D49: =D24*D35*'Starting Data Set'!E22 -> 194722.04 | E49: =(E24+E26)*E35*'Starting Data Set'!F22 -> 222929.42 | F49: =(F24+F26+F27)*F35*'Starting Data Set'!G22 -> 354719.2 | G49: =(G24+G26+G27)*G35*'Starting Data Set'!H22 -> 537178.48 | I49: MK
A50: INFORMATION SYSTEMS EXPENSES | C50: ='OM IS Expenses'!D13+'OM IS Expenses'!D27+'OM IS Expenses'!D29+'OM IS Expenses'!D30 -> 34683.4 | D50: ='OM IS Expenses'!E13+'OM IS Expenses'!E27+'OM IS Expenses'!E29+'OM IS Expenses'!E30 -> 35453.77 | E50: ='OM IS Expenses'!F13+'OM IS Expenses'!F27+'OM IS Expenses'!F29+'OM IS Expenses'!F30 -> 37881.039 | F50: ='OM IS Expenses'!G13+'OM IS Expenses'!G27+'OM IS Expenses'!G29+'OM IS Expenses'!G30 -> 46926.761 | G50: ='OM IS Expenses'!H13+'OM IS Expenses'!H27+'OM IS Expenses'!H29+'OM IS Expenses'!H30 -> 49966.074
...

Sheet Starting Data Set
B3: STARTING DATA SET
C4: START-UP | D4: YEAR 1 | E4: YEAR 2 | F4: YEAR 3 | G4: YEAR 4 | H4: YEAR 5
A7: Gross Capital Expenditure ($/per year) | C7: ='FE Assumptions'!B8 -> 263922.25 | D7: ='OM Capital Expenditures'!E49 -> 8292.1994 | E7: ='OM Capital Expenditures'!F49 -> 15013.686 | F7: ='OM Capital Expenditures'!G49 -> 7646.5788 | G7: ='OM Capital Expenditures'!H49 -> 13307.389 | H7: ='OM Capital Expenditures'!I49 -> 15393.662
A9: Cash Balance as a percent of Sales (%) ($10K required for startup) | C9: ='FE Assumptions'!B11 -> 0 | D9: ='FE Assumptions'!$B$71 -> 0.05 | E9: ='FE Assumptions'!$B$71 -> 0.05 | F9: ='FE Assumptions'!$B$71 -> 0.05 | G9: ='FE Assumptions'!$B$71 -> 0.05 | H9: ='FE Assumptions'!$B$71 -> 0.05
A10: Accounts Receivable Days (DSO) | D10: 45 | E10: 45 | F10: 45 | G10: 45 | H10: 45
A11: Accounts Payable Days (DPO) | D11: 30 | E11: 30 | F11: 30 | G11: 30 | H11: 30
A12: Total Days Inventory on Hand (DOH, includes RM, FPI & WIP. $25K required for start-up.) | C12: ='FE Assumptions'!B11+'FE Assumptions'!B12+'FE Assumptions'!B13 -> 32663.334 | D12: 45 | E12: 44 | F12: 44 | G12: 43 | H12: 41
A15: Sales ($) | D15: ='FE Assumptions'!C28*'FE Assumptions'!C35 -> 1629067.1 | E15: ='FE Assumptions'!D28*'FE Assumptions'!D35 -> 2758562.2 | F15: ='FE Assumptions'!E28*'FE Assumptions'!E35 -> 3503176.7 | G15: ='FE Assumptions'!F28*'FE Assumptions'!F35 -> 5040746.6 | H15: ='FE Assumptions'!G28*'FE Assumptions'!G35 -> 7386204.1
A16: Variable Costs ($) | D16: ='FE Assumptions'!C40 -> 488322.42 | E16: ='FE Assumptions'!D40 -> 853775.5 | F16: ='FE Assumptions'!E40 -> 1154719.8 | G16: ='FE Assumptions'!F40 -> 1643029.9 | H16: ='FE Assumptions'!G40 -> 2442660.6
A17: Fixed Production Costs ($) | D17: ='FE Assumptions'!C41 -> 192923.91 | E17: ='FE Assumptions'!D41 -> 248628.14 | F17: ='FE Assumptions'!E41 -> 290008.74 | G17: ='FE Assumptions'!F41 -> 376145.86 | H17: ='FE Assumptions'!G41 -> 501523.09
A18: Initial Startup Expenses ($) | C18: ='FE Assumptions'!B19 -> 137604.34
A19: Administrative Overhead/Salaries ($) | D19: ='FE Assumptions'!C47 -> 628381.34 | E19: ='FE Assumptions'!D47 -> 668845.24 | F19: ='FE Assumptions'!E47 -> 849961.52 | G19: ='FE Assumptions'!F47 -> 1026543.7 | H19: ='FE Assumptions'!G47 -> 1381304.5
A20: General Operating Expenses not already part of CoGS ($) | D20: ='FE Assumptions'!C50 -> 34683.4 | E20: ='FE Assumptions'!D50 -> 35453.77 | F20: ='FE Assumptions'!E50 -> 37881.039 | G20: ='FE Assumptions'!F50 -> 46926.761 | H20: ='FE Assumptions'!G50 -> 49966.074
A21: Marketing Expenses Excluding Mfg. Reps. Commission ($) | D21: ='FE Assumptions'!C48 -> 268280.33 | E21: ='FE Assumptions'!D48 -> 344232.76 | F21: ='FE Assumptions'!E48 -> 396844.43 | G21: ='FE Assumptions'!F48 -> 503401.33 | H21: ='FE Assumptions'!G48 -> 631633
A22: Manufacturing Reps Commission as percent of Sales (%) | C22: =C18+C12+C7 -> 434189.92 | D22: 0.1 | E22: =D22 -> 0.1 | F22: =E22 -> 0.1 | G22: =F22 -> 0.1 | H22: =G22 -> 0.1
A23: Annual Depreciation ($) | D23: ='OM Capital Expenditures'!E72 -> 12180.851 | E23: ='OM Capital Expenditures'!F72 -> 14263.03 | F23: ='OM Capital Expenditures'!G72 -> 18180.892 | G23: ='OM Capital Expenditures'!H72 -> 20182.206 | H23: ='OM Capital Expenditures'!I72 -> 23109.548
A24: State and Federal Income Tax Rate (%) | C24: ='FE Assumptions'!$B$70 -> 0.27 | D24: ='FE Assumptions'!$B$70 -> 0.27 | E24: ='FE Assumptions'!$B$70 -> 0.27 | F24: ='FE Assumptions'!$B$70 -> 0.27 | G24: ='FE Assumptions'!$B$70 -> 0.27 | H24: ='FE Assumptions'!$B$70 -> 0.27
A26: Discount Rate | C26: ='FE Assumptions'!B67 -> 0.2090185
A28: Terminal Value: Assumes Year 6 FCF is 2% higher than Year 5 and is a declining perpetuity thereafter.
B29: Perpetuity Decline Rate (%): | C29: -0.2

Sheet FE Income Statement
A2: INCOME STATEMENT
A3: *IN US DOLLARS ($) | B3: START-UP | C3: YEAR 1 | D3: YEAR 2 | E3: YEAR 3 | F3: YEAR 4 | G3: YEAR 5
A5: ONLINE REVENUE | C5: ='FE Assumptions'!C25*'FE Assumptions'!C32 -> 236096.69 | D5: ='FE Assumptions'!D25*'FE Assumptions'!D32 -> 835927.95 | E5: ='FE Assumptions'!E25*'FE Assumptions'!E32 -> 1346081.3 | F5: ='FE Assumptions'!F25*'FE Assumptions'!F32 -> 1653788.2 | G5: ='FE Assumptions'!G25*'FE Assumptions'!G32 -> 2278754.9
A6: INDEPENDENT RETAILER REVENUE | C6: ='FE Assumptions'!C24*'FE Assumptions'!C31 -> 1274922.1 | D6: ='FE Assumptions'!D24*'FE Assumptions'!D31 -> 1805604.4 | E6: ='FE Assumptions'!E24*'FE Assumptions'!E31 -> 1817209.8 | F6: ='FE Assumptions'!F24*'FE Assumptions'!F31 -> 2232614.1 | G6: ='FE Assumptions'!G24*'FE Assumptions'!G31 -> 2734505.8
A7: CHAIN RETAILER REVENUE | C7: ='FE Assumptions'!C26*'FE Assumptions'!C33 -> 0 | D7: ='FE Assumptions'!D26*'FE Assumptions'!D33 -> 0 | E7: ='FE Assumptions'!E26*'FE Assumptions'!E33 -> 272581.47 | F7: ='FE Assumptions'!F26*'FE Assumptions'!F33 -> 669784.24 | G7: ='FE Assumptions'!G26*'FE Assumptions'!G33 -> 1640703.5
A8: MASS MERCHANT REVENUE | C8: ='FE Assumptions'!C27*'FE Assumptions'!C34 -> 0 | D8: ='FE Assumptions'!D27*'FE Assumptions'!D34 -> 0 | E8: ='FE Assumptions'!E27*'FE Assumptions'!E34 -> 0 | F8: ='FE Assumptions'!F27*'FE Assumptions'!F34 -> 401870.54 | G8: ='FE Assumptions'!G27*'FE Assumptions'!G34 -> 656281.4
A9: TOTAL REVENUE | C9: ='MK Sales Projections'!C16*$I$10 -> 1629067.1 | D9: ='MK Sales Projections'!D16*$I$10 -> 2758562.2 | E9: ='MK Sales Projections'!E16*$I$10 -> 3503176.7 | F9: ='MK Sales Projections'!F16*$I$10 -> 5040746.6 | G9: ='MK Sales Projections'!G16*$I$10 -> 7386204.1 | I9: Total Revenue Sensitivity
A10: DIRECT MATERIALS COST | C10: =('OM Direct Materials & Direct La'!$F$33)*'FE Assumptions'!C28 -> 315897.37 | D10: ='OM Direct Materials & Direct La'!F51*'FE Assumptions'!D28 -> 543257.64 | E10: ='OM Direct Materials & Direct La'!F68*'FE Assumptions'!E28 -> 707558.04 | F10: ='OM Direct Materials & Direct La'!F85*'FE Assumptions'!F28 -> 1066870.6 | G10: ='OM Direct Materials & Direct La'!F102*'FE Assumptions'!G28 -> 1597081.6 | I10: 1
A11: PER UNIT | C11: =C10/'FE Assumptions'!C28 -> 6.69 | D11: =D10/'FE Assumptions'!D28 -> 6.69 | E11: =E10/'FE Assumptions'!E28 -> 6.69 | F11: =F10/'FE Assumptions'!F28 -> 6.69 | G11: =G10/'FE Assumptions'!G28 -> 6.69
A12: DIRECT LABOR COST | C12: =C13*'FE Assumptions'!C28 -> 133580.41 | D12: =D13*'FE Assumptions'!D28 -> 240778.69 | E12: =E13*'FE Assumptions'!E28 -> 354288.64 | F12: =F13*'FE Assumptions'!F28 -> 437900.76 | G12: =G13*'FE Assumptions'!G28 -> 638970.19
A13: PER UNIT | C13: ='OM Direct Materials & Direct La'!D14 -> 2.8289344 | D13: ='OM Direct Materials & Direct La'!E14 -> 2.965093 | E13: ='OM Direct Materials & Direct La'!F14 -> 3.3498185 | F13: ='OM Direct Materials & Direct La'!G14 -> 2.7459338 | G13: ='OM Direct Materials & Direct La'!H14 -> 2.6765761
A14: INBOUND FREIGHT COST | C14: =C15*'FE Assumptions'!C28 -> 31589.737 | D14: =D15*'FE Assumptions'!D28 -> 54325.764 | E14: =E15*'FE Assumptions'!E28 -> 70755.804 | F14: =F15*'FE Assumptions'!F28 -> 106687.06 | G14: =G15*'FE Assumptions'!G28 -> 159708.16
A15: PER UNIT | C15: ='OM Direct Materials & Direct La'!F34 -> 0.669 | D15: ='OM Direct Materials & Direct La'!F52 -> 0.669 | E15: ='OM Direct Materials & Direct La'!F69 -> 0.669 | F15: ='OM Direct Materials & Direct La'!F86 -> 0.669 | G15: ='OM Direct Materials & Direct La'!F103 -> 0.669
A16: OUTBOUND FREIGHT COST | C16: =C17*'FE Assumptions'!C28 -> 7254.9139 | D16: =D17*'FE Assumptions'!D28 -> 15413.413 | E16: =E17*'FE Assumptions'!E28 -> 22117.312 | F16: =F17*'FE Assumptions'!F28 -> 31571.436 | G16: =G17*'FE Assumptions'!G28 -> 46900.59
A17: PER UNIT | C17: ='OM Location Analysis '!C65 -> 0.15364286 | D17: ='OM Location Analysis '!D65 -> 0.18981 | E17: ='OM Location Analysis '!E65 -> 0.2091204 | F17: ='OM Location Analysis '!F65 -> 0.19797425 | G17: ='OM Location Analysis '!G65 -> 0.19646144
A18: MANUFACTURING OVERHEAD COST | C18: ='Starting Data Set'!D17 -> 192923.91 | D18: ='Starting Data Set'!E17 -> 248628.14 | E18: ='Starting Data Set'!F17 -> 290008.74 | F18: ='Starting Data Set'!G17 -> 376145.86 | G18: ='Starting Data Set'!H17 -> 501523.09
A19: PER UNIT | C19: =C18/'FE Assumptions'!C28 -> 4.085697 | D19: =D18/'FE Assumptions'!D28 -> 3.0617559 | E19: =E18/'FE Assumptions'!E28 -> 2.7420485 | F19: =F18/'FE Assumptions'!F28 -> 2.3586888 | G19: =G18/'FE Assumptions'!G28 -> 2.1008253
A20: TOTAL COST OF GOODS SOLD | C20: =C10+C12+C14+C16+C18 -> 681246.33 | D20: =D10+D12+D14+D16+D18 -> 1102403.6 | E20: =E10+E12+E14+E16+E18 -> 1444728.5 | F20: =F10+F12+F14+F16+F18 -> 2019175.7 | G20: =G10+G12+G14+G16+G18 -> 2944183.6
A21: PER UNIT | C21: =C20/'FE Assumptions'!$C$28 -> 14.427274 | D21: =D20/'FE Assumptions'!D28 -> 13.575659 | E21: =E20/'FE Assumptions'!E28 -> 13.659987 | F21: =F20/'FE Assumptions'!F28 -> 12.661597 | G21: =G20/'FE Assumptions'!G28 -> 12.332863
A22: GROSS PROFIT | C22: =C9-C20 -> 947820.81 | D22: =D9-D20 -> 1656158.6 | E22: =E9-E20 -> 2058448.1 | F22: =F9-F20 -> 3021570.9 | G22: =G9-G20 -> 4442020.4
A23: PER UNIT | C23: =C22/'FE Assumptions'!C28 -> 20.072726 | D23: =D22/'FE Assumptions'!D28 -> 20.394929 | E23: =E22/'FE Assumptions'!E28 -> 19.46274 | F23: =F22/'FE Assumptions'!F28 -> 18.947292 | G23: =G22/'FE Assumptions'!G28 -> 18.607137
A24: ONE-TIME START-UP EXPENSE | B24: ='Starting Data Set'!C18 -> 137604.34
A25: ADMINISTRATIVE OVERHEAD | C25: ='Starting Data Set'!D19 -> 628381.34 | D25: ='Starting Data Set'!E19 -> 668845.24 | E25: ='Starting Data Set'!F19 -> 849961.52 | F25: ='Starting Data Set'!G19 -> 1026543.7 | G25: ='Starting Data Set'!H19 -> 1381304.5
A26: PER UNIT | C26: =C25/'FE Assumptions'!C28 -> 13.307712 | D26: =D25/'FE Assumptions'!D28 -> 8.2365611 | E26: =E25/'FE Assumptions'!E28 -> 8.0364327 | F26: =F25/'FE Assumptions'!F28 -> 6.4371229 | G26: =G25/'FE Assumptions'!G28 -> 5.7861334
A27: GENERAL OPERATING EXPENSES (INFORMATION SYSTEMS) | C27: ='Starting Data Set'!D20 -> 34683.4 | D27: ='Starting Data Set'!E20 -> 35453.77 | E27: ='Starting Data Set'!F20 -> 37881.039 | F27: ='Starting Data Set'!G20 -> 46926.761 | G27: ='Starting Data Set'!H20 -> 49966.074
A28: PER UNIT | C28: =C27/'FE Assumptions'!C28 -> 0.73451687 | D28: =D27/'FE Assumptions'!D28 -> 0.43659897 | E28: =E27/'FE Assumptions'!E28 -> 0.35816729 | F28: =F27/'FE Assumptions'!F28 -> 0.29426252 | G28: =G27/'FE Assumptions'!G28 -> 0.20930241
A29: TOTAL GENERAL & ADMINISTRATIVE EXPENSES | C29: =C25+C27 -> 663064.74 | D29: =D25+D27 -> 704299.01 | E29: =E25+E27 -> 887842.56 | F29: =F25+F27 -> 1073470.4 | G29: =G25+G27 -> 1431270.6
A30: PER UNIT | C30: =C29/'FE Assumptions'!C28 -> 14.042229 | D30: =D29/'FE Assumptions'!D28 -> 8.67316 | E30: =E29/'FE Assumptions'!E28 -> 8.3946 | F30: =F29/'FE Assumptions'!F28 -> 6.7313854 | G30: =G29/'FE Assumptions'!G28 -> 5.9954358
A31: MARKETING EXPENSES (IMC SCHEDULE) | C31: ='Starting Data Set'!D21 -> 268280.33 | D31: ='Starting Data Set'!E21 -> 344232.76 | E31: ='Starting Data Set'!F21 -> 396844.43 | F31: ='Starting Data Set'!G21 -> 503401.33 | G31: ='Starting Data Set'!H21 -> 631633
A32: PER UNIT | C32: =C31/'FE Assumptions'!C28 -> 5.6815777 | D32: =D31/'FE Assumptions'!D28 -> 4.2390885 | E32: =E31/'FE Assumptions'!E28 -> 3.7521858 | F32: =F31/'FE Assumptions'!F28 -> 3.1566667 | G32: =G31/'FE Assumptions'!G28 -> 2.6458415
A33: MANUFACTURER'S SALES COMMISSION | C33: ='Starting Data Set'!D22*'FE Income Statement'!C9 -> 162906.71 | D33: ='Starting Data Set'!E22*'FE Income Statement'!D9 -> 275856.22 | E33: ='Starting Data Set'!F22*'FE Income Statement'!E9 -> 350317.67 | F33: ='Starting Data Set'!G22*'FE Income Statement'!F9 -> 504074.66 | G33: ='Starting Data Set'!H22*'FE Income Statement'!G9 -> 738620.41
A34: TOTAL SALES & MARKETING EXPENSE | C34: =C31+C33 -> 431187.05 | D34: =D31+D33 -> 620088.99 | E34: =E31+E33 -> 747162.1 | F34: =F31+F33 -> 1007476 | G34: =G31+G33 -> 1370253.4
A35: PER UNIT | C35: =C34/'FE Assumptions'!C28 -> 9.1315777 | D35: =D34/'FE Assumptions'!D28 -> 7.6361473 | E35: =E34/'FE Assumptions'!E28 -> 7.0644585 | F35: =F34/'FE Assumptions'!F28 -> 6.3175556 | G35: =G34/'FE Assumptions'!G28 -> 5.7398415
A36: DEPRECIATION | C36: ='Starting Data Set'!D23 -> 12180.851 | D36: ='Starting Data Set'!E23 -> 14263.03 | E36: ='Starting Data Set'!F23 -> 18180.892 | F36: ='Starting Data Set'!G23 -> 20182.206 | G36: ='Starting Data Set'!H23 -> 23109.548
A38: Earnings Before Tax | B38: =B22-B24 -> -137604.34 | C38: =C22-C29-C34-C36 -> -158611.84 | D38: =D22-D29-D34-D36 -> 317507.57 | E38: =E22-E29-E34-E36 -> 405262.6 | F38: =F22-F29-F34-F36 -> 920442.21 | G38: =G22-G29-G34-G36 -> 1617386.9
A39: TAXES | B39: =IF(B38>0,B38*'Starting Data Set'!C24,0) -> 0 | C39: =IF(C38>0,C38*'Starting Data Set'!D24,0) -> 0 | D39: =IF(D38>0,D38*'Starting Data Set'!E24,0) -> 85727.045 | E39: =IF(E38>0,E38*'Starting Data Set'!F24,0) -> 109420.9 | F39: =IF(F38>0,F38*'Starting Data Set'!G24,0) -> 248519.4 | G39: =IF(G38>0,G38*'Starting Data Set'!H24,0) -> 436694.45
A40: PER UNIT | C40: =C39/'FE Assumptions'!C28 -> 0 | D40: =D39/'FE Assumptions'!D28 -> 1.0556942 | E40: =E39/'FE Assumptions'!E28 -> 1.0345806 | F40: =F39/'FE Assumptions'!F28 -> 1.5583846 | G40: =G39/'FE Assumptions'!G28 -> 1.8292652
A42: NET INCOME | B42: =B38-B39 -> -137604.34 | C42: =C38-C39 -> -158611.84 | D42: =D38-D39 -> 231780.53 | E42: =E38-E39 -> 295841.7 | F42: =F38-F39 -> 671922.81 | G42: =G38-G39 -> 1180692.4
A43: PER UNIT | C43: =C42/'FE Assumptions'!C28 -> -3.3590441 | D43: =D42/'FE Assumptions'!D28 -> 2.8542843 | E43: =E42/'FE Assumptions'!E28 -> 2.7971994 | F43: =F42/'FE Assumptions'!F28 -> 4.2134103 | G43: =G42/'FE Assumptions'!G28 -> 4.9457912
C44: =C45-C20 -> 0 | D44: =D45-D20 -> 85727.045 | E44: =E45-E20 -> 109420.9 | F44: =F45-F20 -> 248519.4 | G44: =G45-G20 -> 436694.45
...

Sheet FE Balance Sheet
B2: BALANCE SHEET
B3: *IN US DOLLARS ($) | C3: START-UP | D3: YEAR 1 | E3: YEAR 2 | F3: YEAR 3 | G3: YEAR 4 | H3: YEAR 5 | I3: Comments For Future Buildout
B4: Current Assets
B5: Cash reserves | C5: ='Starting Data Set'!C9 -> 0 | D5: ='Starting Data Set'!D9*'FE Income Statement'!C9 -> 81453.357 | E5: ='Starting Data Set'!E9*'FE Income Statement'!D9 -> 137928.11 | F5: ='Starting Data Set'!F9*'FE Income Statement'!E9 -> 175158.83 | G5: ='Starting Data Set'!G9*'FE Income Statement'!F9 -> 252037.33 | H5: ='Starting Data Set'!H9*'FE Income Statement'!G9 -> 369310.2 | I5: FE assumptions
B6: Accounts Receivable | D6: =('Starting Data Set'!D10/365)*'FE Income Statement'!C9 -> 200843.89 | E6: =('Starting Data Set'!E10/365)*'FE Income Statement'!D9 -> 340096.72 | F6: =('Starting Data Set'!F10/365)*'FE Income Statement'!E9 -> 431898.49 | G6: =('Starting Data Set'!G10/365)*'FE Income Statement'!F9 -> 621461.91 | H6: =('Starting Data Set'!H10/365)*'FE Income Statement'!G9 -> 910627.9 | I6: FE assumptions
B8: Raw Materials & Work in Process Inventory | D8: ='FE Assumptions'!C60 -> 92355.69 | E8: ='FE Assumptions'!D60 -> 127815.22 | F8: ='FE Assumptions'!E60 -> 160107.99 | G8: ='FE Assumptions'!F60 -> 210899.58 | H8: ='FE Assumptions'!G60 -> 268129.3
B9: Finished Goods Inventory | D9: ='FE Assumptions'!C61 -> 28099.493 | E9: ='FE Assumptions'!D61 -> 45471.047 | F9: ='FE Assumptions'!E61 -> 68815.421 | G9: ='FE Assumptions'!F61 -> 96177.534 | H9: ='FE Assumptions'!G61 -> 140237.58
B10: Total Inventory | C10: ='Starting Data Set'!C12 -> 32663.334 | D10: =SUM(D8:D9) -> 120455.18 | E10: =SUM(E8:E9) -> 173286.27 | F10: =SUM(F8:F9) -> 228923.41 | G10: =SUM(G8:G9) -> 307077.12 | H10: =SUM(H8:H9) -> 408366.89 | I10: OM worksheets. By the end of the semester you must separate this line into FPI and RM+WIP
B11: Current Assets | C11: =SUM(C5:C10) -> 32663.334 | D11: =SUM(D5:D10) -> 523207.62 | E11: =SUM(E5:E10) -> 824597.37 | F11: =SUM(F5:F10) -> 1064904.1 | G11: =SUM(G5:G10) -> 1487653.5 | H11: =SUM(H5:H10) -> 2096671.9
B12: Fixed Assets
B13: Gross Fixed Assets | C13: ='Starting Data Set'!C7 -> 263922.25 | D13: =C13+'Starting Data Set'!D7 -> 272214.45 | E13: =D13+'Starting Data Set'!E7 -> 287228.14 | F13: =E13+'Starting Data Set'!F7 -> 294874.71 | G13: =F13+'Starting Data Set'!G7 -> 308182.1 | H13: =G13+'Starting Data Set'!H7 -> 323575.76 | I13: OM asset schedule
B14: Accumulated Depreciation (cumulative) | D14: ='Starting Data Set'!D23 -> 12180.851 | E14: =D14+'Starting Data Set'!E23 -> 26443.882 | F14: =E14+'Starting Data Set'!F23 -> 44624.773 | G14: =F14+'Starting Data Set'!G23 -> 64806.979 | H14: =G14+'Starting Data Set'!H23 -> 87916.527 | I14: FE Income Statement
B15: Net Fixed Assets | C15: =C13-C14 -> 263922.25 | D15: =D13-D14 -> 260033.6 | E15: =E13-E14 -> 260784.25 | F15: =F13-F14 -> 250249.94 | G15: =G13-G14 -> 243375.12 | H15: =H13-H14 -> 235659.24
B17: TOTAL ASSETS | C17: =C11+C15 -> 296585.58 | D17: =D11+D15 -> 783241.21 | E17: =E11+E15 -> 1085381.6 | F17: =F11+F15 -> 1315154.1 | G17: =G11+G15 -> 1731028.6 | H17: =H11+H15 -> 2332331.1
B19: Current Liabilities
B20: Accounts Payable | D20: ='Starting Data Set'!D11*'FE Income Statement'!C20*(1/365) -> 55992.849 | E20: ='Starting Data Set'!E11*'FE Income Statement'!D20*(1/365) -> 90608.518 | F20: ='Starting Data Set'!F11*'FE Income Statement'!E20*(1/365) -> 118744.81 | G20: ='Starting Data Set'!G11*'FE Income Statement'!F20*(1/365) -> 165959.65 | H20: ='Starting Data Set'!H11*'FE Income Statement'!G20*(1/365) -> 241987.7 | I20: FE assumptions
B21: Current Liabilities | C21: =C20 | D21: =D20 -> 55992.849 | E21: =E20 -> 90608.518 | F21: =F20 -> 118744.81 | G21: =G20 -> 165959.65 | H21: =H20 -> 241987.7
B22: Equity
B23: Paid in Capital (cumulative) | C23: =IF('FE Cash Flow'!D15<0,'FE Cash Flow'!D15,0)*-1 -> 434189.92 | D23: =C23+IF('FE Cash Flow'!E15<0,'FE Cash Flow'!E15,0)*-1 -> 1023464.5 | E23: =D23+IF('FE Cash Flow'!F15<0,'FE Cash Flow'!F15,0)*-1 -> 1059208.7 | F23: =E23+IF('FE Cash Flow'!G15<0,'FE Cash Flow'!G15,0)*-1 -> 1059208.7 | G23: =F23+IF('FE Cash Flow'!H15<0,'FE Cash Flow'!H15,0)*-1 -> 1059208.7 | H23: =G23+IF('FE Cash Flow'!I15<0,'FE Cash Flow'!I15,0)*-1 -> 1059208.7 | I23: See FE Cash Flow Tab for any year with Negative FCF
B24: Retained Earnings (cumulative) | C24: ='FE Income Statement'!B48 -> -137604.34 | D24: =C24+'FE Income Statement'!C46-'FE Income Statement'!C47 -> -296216.17 | E24: =D24+'FE Income Statement'!D46-'FE Income Statement'!D47 -> -64435.644 | F24: =E24+'FE Income Statement'!E46-'FE Income Statement'!E47 -> 137200.53 | G24: =F24+'FE Income Statement'!F46-'FE Income Statement'!F47 -> 505860.2 | H24: =G24+'FE Income Statement'!G46-'FE Income Statement'!G47 -> 1031134.7 | I24: See FE Income Statement Tab for changes in Retained Earnings
B25: Total Equity | C25: =C23+C24 -> 296585.58 | D25: =D23+D24 -> 727248.37 | E25: =E23+E24 -> 994773.1 | F25: =F23+F24 -> 1196409.3 | G25: =G23+G24 -> 1565068.9 | H25: =H23+H24 -> 2090343.4
B27: TOTAL LIABILTIES AND EQUITY | C27: =C25+C21 -> 296585.58 | D27: =D25+D21 -> 783241.21 | E27: =E25+E21 -> 1085381.6 | F27: =F25+F21 -> 1315154.1 | G27: =G25+G21 -> 1731028.6 | H27: =H25+H21 -> 2332331.1
B30: Check Total Assets - Total Liabilities & Equity | C30: =C17-C27 -> 0 | D30: =D17-D27 -> 0 | E30: =E17-E27 -> 0 | F30: =F17-F27 -> 0 | G30: =G17-G27 -> -2.3283064e-10 | H30: =H17-H27 -> -4.6566129e-10 | I30: <<Do not delete or hide this line - you may move.
B32: NET WORKING CAPITAL BALANCE | C32: =C11-C21 -> 32663.334 | D32: =D11-D21 -> 467214.77 | E32: =E11-E21 -> 733988.85 | F32: =F11-F21 -> 946159.34 | G32: =G11-G21 -> 1321693.8 | H32: =H11-H21 -> 1854684.2 | I32: link to FE Cash Flow schedule
B34: BALANCE SHEET FINANCIAL RATIOS
B35: DAYS SALES OUTSTANDING (ONLINE) | D35: 5 | E35: 5 | F35: 5 | G35: 5 | H35: 5
B36: DAYS SALES OUTSTANDING (ALL OTHER RETAIL) | D36: =(D6/'FE Income Statement'!C9)*365 -> 45 | E36: =(E6/'FE Income Statement'!D9)*365 -> 45 | F36: =(F6/'FE Income Statement'!E9)*365 -> 45 | G36: =(G6/'FE Income Statement'!F9)*365 -> 45 | H36: =(H6/'FE Income Statement'!G9)*365 -> 45 | I36: These should be calculated Outputs
B37: DAYS INVENTORY OUTSTANDING | D37: =(D10/'FE Income Statement'!C20)*365 -> 64.537804 | E37: =(E10/'FE Income Statement'!D20)*365 -> 57.374165 | F37: =(F10/'FE Income Statement'!E20)*365 -> 57.83581 | G37: =(G10/'FE Income Statement'!F20)*365 -> 55.509358 | H37: =(H10/'FE Income Statement'!G20)*365 -> 50.626568 | I37: These should be calculated Outputs
B38: DAYS PAYABLE OUTSTANDING | D38: ='Starting Data Set'!D11 -> 30 | E38: ='Starting Data Set'!E11 -> 30 | F38: ='Starting Data Set'!F11 -> 30 | G38: ='Starting Data Set'!G11 -> 30 | H38: ='Starting Data Set'!H11 -> 30

Sheet FE Comparable Companies Analysi
B2: COMPS ANALYSIS
B4: COMPANY INFO | E4: VALUATION METRICS | H4: OPERATING METRICS | L4: MARGINS | O4: MULTIPLES & VALUATION | S4: WORKING CAPITAL RATIOS | W4: RETURN METRICS
B5: NAME | C5: TICKER | D5: WEIGHT | E5: ENTERPRISE VALUE | F5: EQUITY VALUE | G5: BETA | H5: REVENUE | I5: GROSS PROFIT | J5: EBITDA | K5: NET INCOME | L5: GROSS MARGIN | M5: EBITDA MARGIN | N5: NET MARGIN | O5: EV/REVENUE | P5: EV/EBITDA | Q5: P/E | R5: WACC | S5: DSO | T5: DIO | U5: DPO | V5: CCC | W5: ROE | X5: ROA | Y5: ROIC
B6: XPLORA | C6: XPLRA | D6: 0.1 | E6: 2772 | F6: 2180 | G6: 0.18 | H6: 754.5 | I6: 376.4 | J6: =E6/P6 -> 10.051855 | K6: -5.51 | L6: =I6/H6 -> 0.49887343 | M6: =J6/H6 -> 0.013322538 | N6: =K6/H6 -> -0.0073028496 | O6: =E6/H6 -> 3.6739563 | P6: 275.77 | Q6: 0 | R6: 0.0657 | S6: 17.86 | T6: 85.69 | U6: 52.4 | V6: =S6+T6-U6 -> 51.15 | W6: -0.0176 | X6: -0.0107 | Y6: -0.0118
B7: MIPS | C7: MIPS AB | D7: 0.3 | E7: =H7*O7 -> 7384.839 | F7: =I7*P7 -> 16682.685 | G7: 1.9 | H7: 456.7 | I7: 330.94 | J7: 18.627 | K7: 13.332 | L7: =I7/H7 -> 0.72463324 | M7: =J7/H7 -> 0.040786074 | N7: =K7/H7 -> 0.02919203 | O7: 16.17 | P7: 50.41 | Q7: 64.47 | R7: 0.117 | S7: 94.65 | T7: 16.52 | U7: 107.76 | V7: =S7+T7-U7 -> 3.41 | W7: 0.2249 | X7: 0.1968 | Y7: 0.2073
B8: RIDEFOX | C8: FOXF | D8: 0.35 | E8: 1230 | F8: 590.24 | G8: 1.5 | H8: =$E$8/O8 -> 1464.2857 | I8: 423.576 | J8: =E8/P8 -> 173.72881 | K8: 6.512 | L8: =I8/H8 -> 0.28927141 | M8: =J8/H8 -> 0.11864407 | N8: =K8/H8 -> 0.0044472195 | O8: 0.84 | P8: 7.08 | Q8: 11.97 | R8: 0.1054 | S8: 44.64 | T8: 143.87 | U8: 51.64 | V8: =S8+T8-U8 -> 136.87 | W8: 0.0054 | X8: 0.0029 | Y8: 0.0254
B9: THULE GROUP | C9: THULE | D9: 0.25 | E9: 3036 | F9: 2679 | G9: 1.37 | H9: 902.142 | I9: 385.214 | J9: 171.427 | K9: 106.09 | L9: =I9/H9 -> 0.4269993 | M9: =J9/H9 -> 0.19002219 | N9: =K9/H9 -> 0.11759789 | O9: =$E$9/H9 -> 3.3653239 | P9: =E9/J9 -> 17.710162 | Q9: 25.45 | R9: 0.0977 | S9: 39.23 | T9: 137.02 | U9: 56.49 | V9: =S9+T9-U9 -> 119.76 | W9: 0.152 | X9: 0.0908 | Y9: 0.12
B10: MEAN | E10: =AVERAGE(E6:E9) -> 3605.7097 | F10: =AVERAGE(F6:F9) -> 5532.9814 | G10: =AVERAGE(G6:G9) -> 1.2375 | H10: =AVERAGE(H6:H9) -> 894.40693 | I10: =AVERAGE(I6:I9) -> 379.0325 | J10: =AVERAGE(J6:J9) -> 93.458667 | K10: =AVERAGE(K6:K9) -> 30.106 | L10: =AVERAGE(L6:L9) -> 0.48494434 | ... Y10: =AVERAGE(Y6:Y9) -> 0.085225
B11: MEDIAN | E11: =MEDIAN(E6:E9) -> 2904 | F11: =MEDIAN(F6:F9) -> 2429.5 | G11: =MEDIAN(G6:G9) -> 1.435 | H11: =MEDIAN(H6:H9) -> 828.321 | I11: =MEDIAN(I6:I9) -> 380.807 | J11: =MEDIAN(J6:J9) -> 95.027 | K11: =MEDIAN(K6:K9) -> 9.922 | L11: =MEDIAN(L6:L9) -> 0.46293636 | ... Y11: =MEDIAN(Y6:Y9) -> 0.0727
B12: WEIGHTED AVERAGE | E12: =SUMPRODUCT($D$6:$D$9,E6:E9) -> 3682.1517 | F12: =SUMPRODUCT($D$6:$D$9,F6:F9) -> 6099.1396 | G12: =SUMPRODUCT($D$6:$D$9,G6:G9) -> 1.4555 | H12: =SUMPRODUCT($D$6:$D$9,H6:H9) -> 950.4955 | I12: =SUMPRODUCT($D$6:$D$9,I6:I9) -> 381.4771 | J12: =SUMPRODUCT($D$6:$D$9,J6:J9) -> 110.25512 | K12: =SUMPRODUCT($D$6:$D$9,K6:K9) -> 32.2503 | L12: =SUMPRODUCT($D$6:$D$9,L6:L9) -> 0.47527213 | ... Y12: =SUMPRODUCT($D$6:$D$9,Y6:Y9) -> 0.0999
B14: CAPITAL ASSET PRICING MODEL
B16: COMPARABLE BETA | C16: =G12 -> 1.4555
B17: RISK-FREE RATE | C17: 0.0415
B18: EQUITY RISK PREMIUM | C18: 0.067
B19: SMALL-CAP PREMIUM | C19: 0.07
B20: COST OF EQUITY | C20: =(C17+(C16*C18))+C19 -> 0.2090185

Sheet FE Cash Flow
B2: STATEMENT OF CASH FLOWS
B3: *IN US DOLLARS ($) | D3: START-UP | E3: YEAR 1 | F3: YEAR 2 | G3: YEAR 3 | H3: YEAR 4 | I3: YEAR 5 | J3: Notes
B6: NET INCOME | D6: ='FE Income Statement'!B42 -> -137604.34 | E6: ='FE Income Statement'!C42 -> -158611.84 | F6: ='FE Income Statement'!D42 -> 231780.53 | G6: ='FE Income Statement'!E42 -> 295841.7 | H6: ='FE Income Statement'!F42 -> 671922.81 | I6: ='FE Income Statement'!G42 -> 1180692.4 | J6: Income Statement
B7: ADD BACK DEPRECIATION | D7: ='FE Income Statement'!B36 | E7: ='FE Income Statement'!C36 -> 12180.851 | F7: ='FE Income Statement'!D36 -> 14263.03 | G7: ='FE Income Statement'!E36 -> 18180.892 | H7: ='FE Income Statement'!F36 -> 20182.206 | I7: ='FE Income Statement'!G36 -> 23109.548 | J7: Income Statement
B8: (-) CHANGE IN FIXED ASSETS | D8: ='Starting Data Set'!C7 -> 263922.25 | E8: ='Starting Data Set'!D7 -> 8292.1994 | F8: ='Starting Data Set'!E7 -> 15013.686 | G8: ='Starting Data Set'!F7 -> 7646.5788 | H8: ='Starting Data Set'!G7 -> 13307.389 | I8: ='Starting Data Set'!H7 -> 15393.662 | J8: OM asset planning, FE Balance Sheet
B9: (+/-) CASH IMPACT OF THE CHANGE IN NWC | D9: ='FE Balance Sheet'!C32 -> 32663.334 | E9: ='FE Balance Sheet'!D32-'FE Balance Sheet'!C32 -> 434551.43 | F9: ='FE Balance Sheet'!E32-'FE Balance Sheet'!D32 -> 266774.08 | G9: ='FE Balance Sheet'!F32-'FE Balance Sheet'!E32 -> 212170.49 | H9: ='FE Balance Sheet'!G32-'FE Balance Sheet'!F32 -> 375534.48 | I9: ='FE Balance Sheet'!H32-'FE Balance Sheet'!G32 -> 532990.36 | J9: Balance Sheet
B11: NET FREE CASH FLOW | D11: =D6+D7-D8-D9 -> -434189.92 | E11: =E6+E7-E8-E9 -> -589274.62 | F11: =F6+F7-F8-F9 -> -35744.206 | G11: =G6+G7-G8-G9 -> 94205.519 | H11: =H6+H7-H8-H9 -> 303263.15 | I11: =I6+I7-I8-I9 -> 655417.94 | J11: Cash Flow: If positive, treat as a dividend,
K12: if negative, treat as additional paid-in capital.
B13: TERMINAL VALUE OF BUSINESS | H13: Terminal Value | I13: =(I11*(1.05^2))/('Starting Data Set'!C26-'Starting Data Set'!C29) -> 1766664 | J13: See Note on Terminal Value on "Starting Data Set" Tab
B15: TOTAL CASH FLOW | D15: =D11 -> -434189.92 | E15: =E11 -> -589274.62 | F15: =F11 -> -35744.206 | G15: =G11 -> 94205.519 | H15: =H11 -> 303263.15 | I15: =I11+I13 -> 2422082 | J15: =I11*(1.02) -> 668526.3 | K15: =J15*(1.02) -> 681896.82
B17: CASH BREAKEVEN? | D17: =IF(D15<0,"NO","YES") -> NO | E17: =IF(E15<0,"NO","YES") -> NO | F17: =IF(F15<0,"NO","YES") -> NO | G17: =IF(G15<0,"NO","YES") -> YES | H17: =IF(H15<0,"NO","YES") -> YES | I17: =IF(I15<0,"NO","YES") -> YES
B18: YEAR | D18: 0 | E18: =IF(E15<0,D18+1,D18+ABS(E15/D15)) -> 1 | F18: =IF(F15<0,E18+1,E18+ABS(F15/E15)) -> 2 | G18: =IF(G15<0,F18+1,(ABS(F15/G15)+F18)) -> 2.3794279 | H18: =G18 -> 2.3794279 | I18: =H18 -> 2.3794279
B20: PAYBACK PERIOD | D20: =D11 -> -434189.92 | E20: =D20+E15 -> -1023464.5 | F20: =E20+F15 -> -1059208.7 | G20: =F20+G15 -> -965003.23 | H20: =G20+H15 -> -661740.08 | I20: =H20+I15 -> 1760341.9
B21: YEAR | D21: 0 | E21: 1 | F21: 2 | G21: 3 | H21: 4 | I21: =H21+(ABS(H20)/I20) -> 4.3759157
B24: NET PRESENT VALUE (INCLUDING TV) | D24: {=NPV('Starting Data Set'!C26,'FE Cash Flow'!E15:I15)+D15} -> 186812.16 | J24: (requires Total cash-flows and a discount rate)
B26: INTERNAL RATE OF RETURN (INCLUDING TV) | D26: =IRR(D15:I15) -> 0.26183911 | J26: (requires Total cash-flows)

Sheet MK Assumptions
B2: MARKETING ASSUMPTIONS | E2: YEAR 1 | G2: ACV | H2: % of Sales | K2: Influencer Type | L2: Following Lower bound | M2: Following Upper Bound | N2: Payment Lower Bound | O2: Payment Upper Bound
E3: Online | G3: 0.12 | H3: =G3/G5 -> 0.85714286 | K3: nano | L3: 0 | M3: 15000 | N3: 500 | O3: 2000
B4: SEGMENT ASSUMPTIONS | E4: Independent | G4: 0.02 | H4: =G4/G5 -> 0.14285714 | K4: micro | L4: 15000 | M4: 75000 | N4: 1000 | O4: 8000
B5: Segment Size | C5: 13412762 | E5: Total ACV | G5: =C9 -> 0.14 | H5: =SUM(H3:H4) -> 1 | K5: Mid-Tier | L5: 75000 | M5: 250000 | N5: 5000 | O5: 20000
B6: Segment Growth Rate | C6: 0.0125 | K6: macro | L6: 250000 | M6: 1000000 | N6: 20000 | O6: 45000
E7: YEAR 2 | G7: ACV | H7: % of Sales | K7: mega | L7: 1000000 | M7: 1000000000 | N7: 45000 | O7: 50000000
B8: ACV GUIDELINES | E8: Online | G8: 0.12 | H8: =G8/G10 -> 0.70588235
B9: Year 1 | C9: 0.14 | E9: Independent | G9: =G10-G8 -> 0.05 | H9: =G9/G10 -> 0.29411765
B10: Year 2 | C10: 0.17 | E10: Total ACV | G10: =C10 -> 0.17 | H10: =SUM(H8:H9) -> 1
B11: Year 3 | C11: 0.22
B12: Year 4 | C12: 0.27 | E12: YEAR 3 | G12: ACV | H12: % of Sales
B13: Year 5 | C13: 0.33 | E13: Online | G13: 0.12 | H13: =G13/$G$16 -> 0.54545455
E14: Independent | G14: 0.08 | H14: =G14/$G$16 -> 0.36363636
B15: RETAILER MARGINS | E15: Chain | G15: =G16-G14-G13 -> 0.02 | H15: =G15/$G$16 -> 0.090909091
B16: Online | C16: 0.5 | E16: Total ACV | G16: =C11 -> 0.22 | H16: =SUM(H13:H15) -> 1
B17: Independent Retailer | C17: 0.45
B18: Chain Retailer | C18: 0.45 | E18: YEAR 4 | G18: ACV | H18: % of Sales
B19: Mass Merchant | C19: 0.4 | E19: Online | G19: 0.12 | H19: =G19/$G$23 -> 0.44444444
E20: Independent | G20: 0.08 | H20: =G20/$G$23 -> 0.2962963
B21: UNITS LOST TO COMPETITION | E21: Chain | G21: =G23-G22-G20-G19 -> 0.04 | H21: =G21/$G$23 -> 0.14814815
B22: Year 1 | C22: 0 | E22: Mass Merchant | G22: 0.03 | H22: =G22/$G$23 -> 0.11111111
B23: Year 2 | C23: 0 | E23: Total ACV | G23: =C12 -> 0.27 | H23: =SUM(H19:H22) -> 1
B24: Year 3 | C24: 0.2
B25: Year 4 | C25: 0.3 | E25: YEAR 5 | G25: ACV | H25: % of Sales
B26: Year 5 | C26: 0.35 | E26: Online | G26: 0.12 | H26: =G26/$G$30 -> 0.36363636
E27: Independent | G27: 0.09 | H27: =G27/$G$30 -> 0.27272727
B28: DISTRIBUTION | C28: RETAIL SELLING PRICE | E28: Chain | G28: =G30-G29-G27-G26 -> 0.08 | H28: =G28/$G$30 -> 0.24242424
B29: Online | C29: 70 | E29: Mass Merchant | G29: 0.04 | H29: =G29/$G$30 -> 0.12121212
B30: Independent | C30: 70 | E30: Total ACV | G30: =C13 -> 0.33 | H30: =SUM(H26:H29) -> 1
B31: Chain | C31: =C30*(1-0.1) -> 63
B32: Mass Merchant | C32: =C31*(1-0.1) -> 56.7

Sheet MK ACV Distribution
B2: RETAILER DISTRIBUTION (ACV)
J3: ACV Sensitivity
B4: YEAR 1 TOTAL ACV | C4: ='MK Assumptions'!C9*J4 -> 0.14 | J4: 1
C5: ONLINE | D5: INDEPENDENT RETAILER | E5: CHAIN RETAILER | F5: MASS MERCHANT
B6: % OF ACV | C6: ='MK Assumptions'!G3 -> 0.12 | D6: ='MK Assumptions'!G4 -> 0.02
B7: % OF SALES | C7: ='MK Assumptions'!H3 -> 0.85714286 | D7: ='MK Assumptions'!H4 -> 0.14285714 | H7: TOTAL UNITS | J7: ERROR CHECK
B8: YEAR 1 UNITS | C8: ='MK Sales Projections'!C14*'MK ACV Distribution'!C7 -> 40473.718 | D8: =D7*'MK Sales Projections'!C14 -> 6745.6196 | H8: =SUM(C8:F8) -> 47219.337 | J8: ='MK Sales Projections'!C14 -> 47219.337
B11: YEAR 2 TOTAL ACV | C11: ='MK Assumptions'!C10*J4 -> 0.17
C12: ONLINE | D12: INDEPENDENT RETAILER | E12: CHAIN RETAILER | F12: MASS MERCHANT
B13: % OF ACV | C13: ='MK Assumptions'!G8 -> 0.12 | D13: ='MK Assumptions'!G9 -> 0.05
B14: % OF SALES | C14: ='MK Assumptions'!H8 -> 0.70588235 | D14: ='MK Assumptions'!H9 -> 0.29411765 | H14: TOTAL UNITS | J14: ERROR CHECK
B15: YEAR 1 UNITS | C15: =C14*'MK Sales Projections'!$D$14 -> 57320.774 | D15: =D14*'MK Sales Projections'!$D$14 -> 23883.656 | H15: =SUM(C15:F15) -> 81204.43 | J15: ='MK Sales Projections'!D14 -> 81204.43
B18: YEAR 3 TOTAL ACV | C18: ='MK Assumptions'!C11*J4 -> 0.22
C19: ONLINE | D19: INDEPENDENT RETAILER | E19: CHAIN RETAILER | F19: MASS MERCHANT
B20: % OF ACV | C20: ='MK Assumptions'!G13 -> 0.12 | D20: ='MK Assumptions'!G14 -> 0.08 | E20: ='MK Assumptions'!G15 -> 0.02
B21: % OF SALES | C21: ='MK Assumptions'!H13 -> 0.54545455 | D21: ='MK Assumptions'!H14 -> 0.36363636 | E21: ='MK Assumptions'!H15 -> 0.090909091 | H21: TOTAL UNITS | J21: ERROR CHECK
B22: YEAR 1 UNITS | C22: =C21*'MK Sales Projections'!$E$14 -> 57689.2 | D22: =D21*'MK Sales Projections'!$E$14 -> 38459.467 | E22: =E21*'MK Sales Projections'!$E$14 -> 9614.8667 | H22: =SUM(C22:F22) -> 105763.53 | J22: ='MK Sales Projections'!E14 -> 105763.53
B25: YEAR 4 TOTAL ACV | C25: ='MK Assumptions'!C12*J4 -> 0.27
C26: ONLINE | D26: INDEPENDENT RETAILER | E26: CHAIN RETAILER | F26: MASS MERCHANT
B27: % OF ACV | C27: ='MK Assumptions'!G19 -> 0.12 | D27: ='MK Assumptions'!G20 -> 0.08 | E27: ='MK Assumptions'!G21 -> 0.04 | F27: ='MK Assumptions'!G22 -> 0.03
B28: % OF SALES | C28: ='MK Assumptions'!H19 -> 0.44444444 | D28: ='MK Assumptions'!H20 -> 0.2962963 | E28: ='MK Assumptions'!H21 -> 0.14814815 | F28: ='MK Assumptions'!H22 -> 0.11111111 | H28: TOTAL UNITS | J28: ERROR CHECK
B29: YEAR 1 UNITS | C29: =C28*'MK Sales Projections'!$F$14 -> 70876.639 | D29: =D28*'MK Sales Projections'!$F$14 -> 47251.093 | E29: =E28*'MK Sales Projections'!$F$14 -> 23625.546 | F29: =F28*'MK Sales Projections'!$F$14 -> 17719.16 | H29: =SUM(C29:F29) -> 159472.44 | J29: ='MK Sales Projections'!F14 -> 159472.44
B32: YEAR 5 TOTAL ACV | C32: ='MK Assumptions'!C26*J4 -> 0.35
C33: ONLINE | D33: INDEPENDENT RETAILER | E33: CHAIN RETAILER | F33: MASS MERCHANT
B34: % OF ACV | C34: ='MK Assumptions'!G26 -> 0.12 | D34: ='MK Assumptions'!G27 -> 0.09 | E34: ='MK Assumptions'!G28 -> 0.08 | F34: ='MK Assumptions'!G29 -> 0.04
B35: % OF SALES | C35: ='MK Assumptions'!H26 -> 0.36363636 | D35: ='MK Assumptions'!H27 -> 0.27272727 | E35: ='MK Assumptions'!H28 -> 0.24242424 | F35: ='MK Assumptions'!H29 -> 0.12121212 | H35: TOTAL UNITS | J35: ERROR CHECK
B36: YEAR 1 UNITS | C36: =C35*'MK Sales Projections'!$G$14 -> 86809.709 | D36: =D35*'MK Sales Projections'!$G$14 -> 65107.282 | E36: =E35*'MK Sales Projections'!$G$14 -> 57873.139 | F36: =F35*'MK Sales Projections'!$G$14 -> 28936.57 | H36: =SUM(C36:F36) -> 238726.7 | J36: ='MK Sales Projections'!G14 -> 238726.7

Sheet MK Demand Curve & Purchase Inte
B2: PURCHASE INTENT
B4: PIVOT TABLE FOR PURCHASE INTENT
B5: PURCHASE INTENT | C5: 55 | D5: 60 | E5: 70 | F5: 80 | G5: 85 | H5: GRAND TOTAL
B6: DEFINITELY BUY | C6: 10 | D6: 9 | E6: 6 | F6: 9 | G6: 9 | H6: 43
B7: PROBABLY BUY | C7: 7 | D7: 8 | E7: 6 | F7: 9 | G7: 5 | H7: 35
B8: MAYBE BUY | C8: 3 | D8: 6 | E8: 6 | F8: 3 | G8: 4 | H8: 22
B9: PROBABLY NOT BUY | C9: 1 | D9: 1 | E9: 3 | F9: 2 | G9: 5 | H9: 12
B10: DEFINITELY NOT BUY | C10: 1 | D10: 1 | E10: 3 | F10: 1 | G10: 1 | H10: 7
B11: GRAND TOTAL | C11: 22 | D11: 25 | E11: 24 | F11: 24 | G11: 24 | H11: 119
B13: CUMULATIVE PURCHASE INTENT
B14: PURCHASE INTENT | C14: 55 | D14: 60 | E14: 70 | F14: 80 | G14: 85
B15: CUMULATIVE NUMBER AT PROBABLY BUY | C15: 35 | D15: 28 | E15: 20 | F15: 14 | G15: 5
B16: ADJUSTED NUMBER AT PROBABLY BUY | C16: =C15*0.3 -> 10.5 | D16: =D15*0.3 -> 8.4 | E16: =E15*0.3 -> 6 | F16: =F15*0.3 -> 4.2 | G16: =G15*0.3 -> 1.5
B17: CUMULATIVE NUMBER AT DEFINITELY BUY | C17: 43 | D17: 33 | E17: 24 | F17: 18 | G17: 9
B18: ADJUSTED NUMBER AT DEFINITELY BUY | C18: =C17*0.8 -> 34.4 | D18: =D17*0.8 -> 26.4 | E18: =E17*0.8 -> 19.2 | F18: =F17*0.8 -> 14.4 | G18: =G17*0.8 -> 7.2
B19: SUM OF PURCHASE INTENT | C19: 44.9 | D19: 34.8 | E19: 25.2 | F19: 18.6 | G19: 8.7
B20: TOTAL SAMPLE SIZE | C20: 119 | D20: 119 | E20: 119 | F20: 119 | G20: 119
B21: ADJUSTMENT FOR TOTAL SAMPLE SIZE | C21: =C19/C20 -> 0.37731092 | D21: =D19/D20 -> 0.29243697 | E21: =E19/E20 -> 0.21176471 | F21: =F19/F20 -> 0.15630252 | G21: =G19/G20 -> 0.073109244
B23: PRICE | C23: CUMULATIVE PURCHASE INTENT
B24: 55 | C24: =C21 -> 0.37731092
B25: 60 | C25: =D21 -> 0.29243697
B26: 70 | C26: =E21 -> 0.21176471
B27: 80 | C27: =F21 -> 0.15630252
B28: 85 | C28: =G21 -> 0.073109244
B30: SLOPE OF CUMULATIVE P.I. | C30: INTERCEPT
B31: -0.009114415 | C31: 0.86019392

Sheet MK Sales Projections
B2: BASES MODEL (YEARS 1-5)
B4: BASES FORECAST | C4: YEAR 1 | D4: YEAR 2 | E4: YEAR 3 | F4: YEAR 4 | G4: YEAR 5
B5: TARGET MARKET SIZE | C5: ='MK Assumptions'!C5*I6 -> 13412762 | D5: =(C5*(1+'MK Assumptions'!$C$6)-'MK Sales Projections'!C14)*$I$6 -> 13533202 | E5: =(D5*(1+'MK Assumptions'!$C$6)-'MK Sales Projections'!D14)*$I$6 -> 13621163 | F5: =(E5*(1+'MK Assumptions'!$C$6)-'MK Sales Projections'!E14)*$I$6 -> 13685664 | G5: =(F5*(1+'MK Assumptions'!$C$6)-'MK Sales Projections'!F14)*$I$6 -> 13697262 | I5: Target Market Size Sensitivity
B6: ADJUSTED Purchase Intent @ $ Average Weighted Retail Price | C6: =('MK Weighted Price Calculations'!C11*'MK Demand Curve & Purchase Inte'!B31)+'MK Demand Curve & Purchase Inte'!C31 -> 0.22218487 | D6: =('MK Weighted Price Calculations'!C20*'MK Demand Curve & Purchase Inte'!B31)+'MK Demand Curve & Purchase Inte'!C31 -> 0.22218487 | E6: =('MK Weighted Price Calculations'!C29*'MK Demand Curve & Purchase Inte'!B31)+'MK Demand Curve & Purchase Inte'!C31 -> 0.22798496 | F6: =('MK Weighted Price Calculations'!C38*'MK Demand Curve & Purchase Inte'!B31)+'MK Demand Curve & Purchase Inte'!C31 -> 0.24510594 | G6: =('MK Weighted Price Calculations'!C47*'MK Demand Curve & Purchase Inte'!B31)+'MK Demand Curve & Purchase Inte'!C31 -> 0.2523453 | I6: 1
B7: Awareness | C7: ='MK IMC Schedule'!P24*I9 -> 0.11317725 | D7: ='MK IMC Schedule'!P48*I9 -> 0.15886043 | E7: ='MK IMC Schedule'!P72*I9 -> 0.19350977 | F7: ='MK IMC Schedule'!P96*I9 -> 0.2515383 | G7: ='MK IMC Schedule'!P120*I9 -> 0.32199172
B8: ACV | C8: ='MK Assumptions'!C9 -> 0.14 | D8: ='MK Assumptions'!C10 -> 0.17 | E8: ='MK Assumptions'!C11 -> 0.22 | F8: ='MK Assumptions'!C12 -> 0.27 | G8: ='MK Assumptions'!C13 -> 0.33 | I8: Awareness Sensitivity
B9: Units at Trial | C9: 1 | D9: 1 | E9: 1 | F9: 1 | G9: 1 | I9: 1
B10: TRIAL UNITS | C10: =C5*C6*C7*C8*C9 -> 47219.337 | D10: =D5*D6*D7*D8*D9 -> 81204.43 | E10: =E5*E6*E7*E8*E9 -> 132204.42 | F10: =F5*F6*F7*F8*F9 -> 227817.77 | G10: =G5*G6*G7*G8*G9 -> 367271.84
B11: Repeat Units | C11: 0 | D11: 0 | E11: 0 | F11: 0 | G11: 0
B12: BASES Sales Units (before competition) | C12: =C10*$I$13 -> 47219.337 | D12: =D10*$I$13 -> 81204.43 | E12: =E10*$I$13 -> 132204.42 | F12: =F10*$I$13 -> 227817.77 | G12: =G10*$I$13 -> 367271.84 | I12: BASES Sales Units Sensitivity
B13: Competition Adjustment (units lost to competition) | C13: 0 | D13: 0 | E13: 0.2 | F13: 0.3 | G13: 0.35 | I13: 1
B14: TOTAL UNITS | C14: =C12*(1-C13) -> 47219.337 | D14: =D12*(1-D13) -> 81204.43 | E14: =E12*(1-E13) -> 105763.53 | F14: =F12*(1-F13) -> 159472.44 | G14: =G12*(1-G13) -> 238726.7
B15: Average WEIGHTED manufacturer's selling price to channel | C15: ='MK Weighted Price Calculations'!C10 -> 34.5 | D15: ='MK Weighted Price Calculations'!C19 -> 33.970588 | E15: ='MK Weighted Price Calculations'!C28 -> 33.122727 | F15: ='MK Weighted Price Calculations'!C37 -> 31.608889 | G15: ='MK Weighted Price Calculations'!C46 -> 30.94
B16: MANUFACTURER SALES ($) | C16: =C15*C14 -> 1629067.1 | D16: =D15*D14 -> 2758562.2 | E16: =E15*E14 -> 3503176.7 | F16: =F15*F14 -> 5040746.6 | G16: =G15*G14 -> 7386204.1
B17: YEAR 5 TOTAL VARIABLE COST | G17: ='FE Assumptions'!G38 -> 10.035576
B18: YEAR 5 IMC COST | G18: ='MK IMC Schedule'!O127 -> 631633
B19: ESTIMATED PRODUCT LIFE CYCLE IN YEARS | G19: 7
D24: YEAR | E24: Revenue | F24: Awareness | G24: All-Commodity Volume | H24: Purchase Intent
D25: 1 | E25: =C16 -> 1629067.1 | F25: =C8 -> 0.14 | G25: =C8 -> 0.14 | H25: =C6 -> 0.22218487
D26: 2 | E26: =D16 -> 2758562.2 | F26: =D8 -> 0.17 | G26: =D8 -> 0.17 | H26: =D6 -> 0.22218487
D27: 3 | E27: =E16 -> 3503176.7 | F27: =E8 -> 0.22 | G27: =E8 -> 0.22 | H27: =E6 -> 0.22798496
D28: 4 | E28: =F16 -> 5040746.6 | F28: =F8 -> 0.27 | G28: =F8 -> 0.27 | H28: =F6 -> 0.24510594
D29: 5 | E29: =G16 -> 7386204.1 | F29: =G8 -> 0.33 | G29: =G8 -> 0.33 | H29: =G6 -> 0.2523453
D32: Year | E32: 1 | F32: 2 | G32: 3 | H32: 4 | I32: 5
D33: Revenue | E33: =E25 -> 1629067.1 | F33: =E26 -> 2758562.2 | G33: =E27 -> 3503176.7 | H33: =E28 -> 5040746.6 | I33: =E29 -> 7386204.1
D34: Purchase Intent | E34: =H25 -> 0.22218487 | F34: =H26 -> 0.22218487 | G34: =H27 -> 0.22798496 | H34: =H28 -> 0.24510594 | I34: =H29 -> 0.2523453
D35: Awareness | E35: =C7 -> 0.11317725 | F35: =D7 -> 0.15886043 | G35: =E7 -> 0.19350977 | H35: =F7 -> 0.2515383 | I35: =G7 -> 0.32199172
D36: All-Commodity Volume | E36: =C8 -> 0.14 | F36: =D8 -> 0.17 | G36: =E8 -> 0.22 | H36: =F8 -> 0.27 | I36: =G8 -> 0.33
D37: Units Lost to Competition | E37: =C13 -> 0 | F37: =D13 -> 0 | G37: =E13 -> 0.2 | H37: =F13 -> 0.3 | I37: =G13 -> 0.35

Sheet MK Weighted Price Calculations
B2: WEIGHTED PRICE CALCULATIONS
B4: AVERAGE WEIGHTED MANUFACTURER's SELLING PRICE (YEAR 1)
C5: % MANU TOTAL UNITS | D5: MANU. SELLING PRICE | E5: RETAILER MARGIN | F5: RETAIL SELLING PRICE
B6: UNITS ONLINE | C6: ='MK Assumptions'!H3 -> 0.85714286 | D6: =F6*E6 -> 35 | E6: ='MK Assumptions'!$C$16 -> 0.5 | F6: ='MK Assumptions'!C29 -> 70
B7: UNITS INTO INDEPENDENT RETAILERS | C7: ='MK Assumptions'!H4 -> 0.14285714 | D7: =F7*E7 -> 31.5 | E7: ='MK Assumptions'!$C$17 -> 0.45 | F7: ='MK Assumptions'!C30 -> 70
B8: UNITS INTO CHAIN RETAILERS | C8: 0 | D8: =F8*E8 -> 0 | E8: ='MK Assumptions'!$C$18 -> 0.45 | F8: 0
B9: UNITS INTO MASS MERCHANTS | C9: 0 | D9: =F9*E9 -> 0 | E9: ='MK Assumptions'!$C$19 -> 0.4 | F9: 0
B10: AVERAGE WEIGHTED MANUFACTURING PRICE | C10: =(C6*D6)+(C7*D7) -> 34.5
B11: AVERAGE WEIGHTED RETAIL PRICE | C11: =(C6*F6)+(C7*F7) -> 70
B13: AVERAGE WEIGHTED MANUFACTURER's SELLING PRICE (YEAR 2)
C14: % MANU TOTAL UNITS | D14: MANU. SELLING PRICE | E14: RETAILER MARGIN | F14: RETAIL SELLING PRICE
B15: UNITS ONLINE | C15: ='MK Assumptions'!H8 -> 0.70588235 | D15: =F15*E15 -> 35 | E15: ='MK Assumptions'!$C$16 -> 0.5 | F15: ='MK Assumptions'!C29 -> 70
B16: UNITS INTO INDEPENDENT RETAILERS | C16: ='MK Assumptions'!H9 -> 0.29411765 | D16: =F16*E16 -> 31.5 | E16: ='MK Assumptions'!$C$17 -> 0.45 | F16: ='MK Assumptions'!C30 -> 70
B17: UNITS INTO CHAIN RETAILERS | C17: 0 | D17: =F17*E17 -> 0 | E17: ='MK Assumptions'!$C$18 -> 0.45 | F17: 0
B18: UNITS INTO MASS MERCHANTS | C18: 0 | D18: =F18*E18 -> 0 | E18: ='MK Assumptions'!$C$19 -> 0.4 | F18: 0
B19: AVERAGE WEIGHTED MANUFACTURING PRICE | C19: =(C15*D15)+(C16*D16) -> 33.970588
B20: AVERAGE WEIGHTED RETAIL PRICE | C20: =(C15*F15)+(C16*F16) -> 70
B22: AVERAGE WEIGHTED MANUFACTURER's SELLING PRICE (YEAR 2)
C23: % MANU TOTAL UNITS | D23: MANU. SELLING PRICE | E23: RETAILER MARGIN | F23: RETAIL SELLING PRICE
B24: UNITS ONLINE | C24: ='MK Assumptions'!H13 -> 0.54545455 | D24: =F24*E24 -> 35 | E24: ='MK Assumptions'!$C$16 -> 0.5 | F24: ='MK Assumptions'!C29 -> 70
B25: UNITS INTO INDEPENDENT RETAILERS | C25: ='MK Assumptions'!H14 -> 0.36363636 | D25: =F25*E25 -> 31.5 | E25: ='MK Assumptions'!$C$17 -> 0.45 | F25: ='MK Assumptions'!C30 -> 70
B26: UNITS INTO CHAIN RETAILERS | C26: ='MK Assumptions'!H15 -> 0.090909091 | D26: =F26*E26 -> 28.35 | E26: ='MK Assumptions'!$C$18 -> 0.45 | F26: ='MK Assumptions'!C31 -> 63
B27: UNITS INTO MASS MERCHANTS | C27: 0 | D27: =F27*E27 -> 0 | E27: ='MK Assumptions'!$C$19 -> 0.4 | F27: 0
B28: AVERAGE WEIGHTED MANUFACTURING PRICE | C28: =(C24*D24)+(C25*D25)+(C26*D26) -> 33.122727
B29: AVERAGE WEIGHTED RETAIL PRICE | C29: =(C24*F24)+(C25*F25)+(C26*F26) -> 69.363636
B31: AVERAGE WEIGHTED MANUFACTURER's SELLING PRICE (YEAR 1)
C32: % MANU TOTAL UNITS | D32: MANU. SELLING PRICE | E32: RETAILER MARGIN | F32: RETAIL SELLING PRICE
B33: UNITS ONLINE | C33: ='MK Assumptions'!H19 -> 0.44444444 | D33: =F33*E33 -> 35 | E33: ='MK Assumptions'!$C$16 -> 0.5 | F33: ='MK Assumptions'!C29 -> 70
B34: UNITS INTO INDEPENDENT RETAILERS | C34: ='MK Assumptions'!H20 -> 0.2962963 | D34: =F34*E34 -> 31.5 | E34: ='MK Assumptions'!$C$17 -> 0.45 | F34: ='MK Assumptions'!C30 -> 70
B35: UNITS INTO CHAIN RETAILERS | C35: ='MK Assumptions'!H21 -> 0.14814815 | D35: =F35*E35 -> 28.35 | E35: ='MK Assumptions'!$C$18 -> 0.45 | F35: ='MK Assumptions'!C31 -> 63
B36: UNITS INTO MASS MERCHANTS | C36: ='MK Assumptions'!H22 -> 0.11111111 | D36: =F36*E36 -> 22.68 | E36: ='MK Assumptions'!$C$19 -> 0.4 | F36: ='MK Assumptions'!C32 -> 56.7
B37: AVERAGE WEIGHTED MANUFACTURING PRICE | C37: =(C33*D33)+(C34*D34)+(C35*D35)+(C36*D36) -> 31.608889
B38: AVERAGE WEIGHTED RETAIL PRICE | C38: =(C33*F33)+(C34*F34)+(C35*F35)+(C36*F36) -> 67.485185
B40: AVERAGE WEIGHTED MANUFACTURER's SELLING PRICE (YEAR 1)
C41: % MANU TOTAL UNITS | D41: MANU. SELLING PRICE | E41: RETAILER MARGIN | F41: RETAIL SELLING PRICE
B42: UNITS ONLINE | C42: ='MK Assumptions'!H26 -> 0.36363636 | D42: =F42*E42 -> 35 | E42: ='MK Assumptions'!$C$16 -> 0.5 | F42: ='MK Assumptions'!C29 -> 70
B43: UNITS INTO INDEPENDENT RETAILERS | C43: ='MK Assumptions'!H27 -> 0.27272727 | D43: =F43*E43 -> 31.5 | E43: ='MK Assumptions'!$C$17 -> 0.45 | F43: ='MK Assumptions'!C30 -> 70
B44: UNITS INTO CHAIN RETAILERS | C44: ='MK Assumptions'!H28 -> 0.24242424 | D44: =F44*E44 -> 28.35 | E44: ='MK Assumptions'!$C$18 -> 0.45 | F44: ='MK Assumptions'!C31 -> 63
B45: UNITS INTO MASS MERCHANTS | C45: ='MK Assumptions'!H29 -> 0.12121212 | D45: =F45*E45 -> 22.68 | E45: ='MK Assumptions'!$C$19 -> 0.4 | F45: ='MK Assumptions'!C32 -> 56.7
B46: AVERAGE WEIGHTED MANUFACTURING PRICE | C46: =(C42*D42)+(C43*D43)+(C44*D44)+(C45*D45) -> 30.94
...

Sheet MK IMC Schedule
B2: IMC SCHEDULE (YEARS 1-5)
B4: WEBSITE | C4: JAN | D4: FEB | E4: MAR | F4: APR | G4: MAY | H4: JUN | I4: JUL | J4: AUG | K4: SEP | L4: OCT | M4: NOV | N4: DEC | O4: TOTAL COST | P4: AWARENESS | Q4: CPM/CPC
B5: Website | O5: ='OM IS Expenses'!C26*12 -> 300
B6: Production Costs | O6: =O7-O5 -> 39942.05
B7: TOTAL IMC BUDGET | O7: =0.15*O31 -> 40242.05
P10: SEGMENT SIZE | Q10: ='MK Sales Projections'!C5 -> 13412762
B11: YEAR 1 | C11: JAN | D11: FEB | E11: MAR | F11: APR | G11: MAY | H11: JUN | I11: JUL | J11: AUG | K11: SEP | L11: OCT | M11: NOV | N11: DEC | O11: TOTAL COST | P11: AWARENESS | Q11: CPM/CPC | S11: OUT OF HOME ADVERTISING (YEAR 1)
B12: PULL | S12: CITIES | T12: COST PER AD | U12: ADS PER CITY | V12: TIMES PER YEAR | W12: AWARENESS RATE PER $1000
B13: Paid Media | S13: NEW YORK CITY | T13: 1050 | U13: 9 | V13: 4 | W13: 0.0004
B14: Social Media | O14: =T22 -> 5000 | P14: =X22 -> 0.0051205947 | Q14: 9.1 | S14: WASHINGTON D.C. | T14: 555
B15: Youtube Ads | O15: =T23 -> 5000 | P15: =X23 -> 0.004853897 | Q15: 9.6 | S15: BOSTON | T15: 555
B16: Google Search | O16: =T24 -> 10000 | P16: =(O16/Q16)/Q10 -> 0.00074555859 | Q16: 1 | S16: SAN FRANCISCO | T16: 2745
B17: Influencer Marketing | O17: =W29 -> 8137.3333 | P17: =X29 -> 0.01 | S17: MINNEAPOLIS | T17: 1804
B18: OOH Advertising | O18: =5*T18*U13*V13*0.75 -> 181143 | P18: =O18/1000*W13 -> 0.0724572 | S18: AVERAGE COST PER AD | T18: =AVERAGE(T13:T17) -> 1341.8
B19: Owned Media
B20: Website | O20: 2000 | P20: 0 | S20: PAID MEDIA (YEAR 1)
B21: Earned Media | S21: MEDIA TYPE | T21: BUDGET | U21: TARGETED IMPRESSIONS | V21: AD IMPACT TARGET IMPRESSIONS | W21: PEOPLE AWARE | X21: AWARENESS
B22: Social Media Amp & WOM | O22: 0 | P22: 0.01 | S22: SOCIAL MEDIA | T22: 5000 | U22: =(T22/Q14)*U25 -> 549450.55 | V22: =U22*V25 -> 274725.27 | W22: =V22/W25 -> 68681.319 | X22: =W22/$Q$10 -> 0.0051205947
B23: Public Relations | O23: 5000 | P23: 0.01 | S23: YOUTUBE | T23: 5000 | U23: =T23/Q15*U25 -> 520833.33 | V23: =U23*V25 -> 260416.67 | W23: =V23/W25 -> 65104.167 | X23: =W23/$Q$10 -> 0.004853897
B24: TOTAL PULL | O24: =SUM(O14:O23) -> 216280.33 | P24: =SUM(P14:P23) -> 0.11317725 | S24: GOOGLE DESKTOP | T24: 10000
B25: PUSH | T25: CPM STRATEGY | U25: 1000 | V25: 0.5 | W25: 4
B26: Outdoor Demo Trade Show | O26: 16000
B27: Life Time Sea Otter Classic Trade Show | O27: 16000 | S27: INFLUENCER MARKETING (YEAR 1)
B28: Safe Routes Partnership | O28: 0 | S28: INFLUENCER | T28: FOLLOWING | U28: INFLUENCER TYPE | V28: PAYMENTS BASED ON SIZE | W28: TOTAL INLUENCER SPEND | X28: AWARENESS (GIVEN)
B29: TOTAL PUSH | O29: =SUM(O26:O28) -> 32000 | S29: TwoWheelingTots | T29: 7900 | U29: Nano | V29: ='MK Assumptions'!N$3+(T29-'MK Assumptions'!L$3)*(('MK Assumptions'!O$3-'MK Assumptions'!N$3)/('MK Assumptions'!M$3-'MK Assumptions'!L$3)) -> 1290 | W29: =SUM(V29:V33) -> 8137.3333 | X29: 0.01
B30: Production Costs | O30: 20000 | S30: RascalRides | T30: 2090 | U30: Nano | V30: ='MK Assumptions'!N$3+(T30-'MK Assumptions'!L$3)*(('MK Assumptions'!O$3-'MK Assumptions'!N$3)/('MK Assumptions'!M$3-'MK Assumptions'!L$3)) -> 709
B31: TOTAL IMC BUDGET | O31: =O30+O29+O24 -> 268280.33 | S31: KellyJaneCollinge | T31: 13400 | U31: Nano | V31: ='MK Assumptions'!N$3+(T31-'MK Assumptions'!L$3)*(('MK Assumptions'!O$3-'MK Assumptions'!N$3)/('MK Assumptions'!M$3-'MK Assumptions'!L$3)) -> 1840
N32: PERCENTAGE OF SALES | O32: =O31/'MK Sales Projections'!C16 -> 0.16468341 | S32: TheMultiDad | T32: 16600 | U32: Micro | V32: ='MK Assumptions'!N$4+(T32-'MK Assumptions'!L$4)*(('MK Assumptions'!O$4-'MK Assumptions'!N$4)/('MK Assumptions'!M$4-'MK Assumptions'!L$4)) -> 1186.6667
S33: DadBodCycling | T33: 33100 | U33: Micro | V33: ='MK Assumptions'!N$4+(T33-'MK Assumptions'!L$4)*(('MK Assumptions'!O$4-'MK Assumptions'!N$4)/('MK Assumptions'!M$4-'MK Assumptions'!L$4)) -> 3111.6667
P34: SEGMENT SIZE | Q34: ='MK Sales Projections'!D5 -> 13533202
B35: YEAR 2 | C35: JAN | D35: FEB | E35: MAR | F35: APR | G35: MAY | H35: JUN | I35: JUL | J35: AUG | K35: SEP | L35: OCT | M35: NOV | N35: DEC | O35: TOTAL COST | P35: AWARENESS | Q35: CPM | S35: OUT OF HOME ADVERTISING (YEAR 2)
B36: PULL | S36: CITIES | T36: COST PER AD | U36: ADS PER CITY | V36: TIMES PER YEAR | W36: AWARENESS RATE PER $1000
B37: Paid Media | S37: NEW YORK CITY | T37: 1050 | U37: 9 | V37: 4 | W37: 0.0004
B38: Social Media | O38: =T46 -> 10000 | P38: =X46 -> 0.010241189 | Q38: 9.1 | S38: SAN FRANCISCO | T38: 2475
B39: Youtube Ads | O39: =T47 -> 10000 | P39: =X47 -> 0.0097077941 | Q39: 9.6 | S39: WASHINGTON DC | T39: 555
B40: Google Search | O40: =T48 -> 20000 | P40: =(O40/Q40)/Q34 -> 0.0014778468 | Q40: 1 | S40: MINNEAPOLIS | T40: 1804
B41: Influencer Marketing | O41: =W53 -> 14148.762 | P41: =X53 -> 0.02 | S41: AUSTIN | T41: 535
B42: OOH Advertising | O42: =5*T42*U37*V37 -> 231084 | P42: =O42/1000*W37 -> 0.0924336 | S42: AVERAGE COST PER AD | T42: =AVERAGE(T37:T41) -> 1283.8
B43: Owned Media
B44: Website | O44: 2000 | P44: 0 | S44: PAID MEDIA (YEAR 2)
...

Sheet OM Assumptions
B2: OM ASSUMPTIONS | E2: SG&A
E3: Executive Salaries as a % of Manu. Sales | F3: 0.01
B4: DIRECT LABOR | E4: Labor Wage Growth Rate | F4: =C8 -> 0.03
B5: Work Days Per Year | C5: 250 | E5: Salesperson Commission Rate | F5: 0.01
B6: Work Hours per Day | C6: 8
B7: Work Hours per Year | C7: =C5*C6 -> 2000
B8: Direct Labor Rate Growth | C8: 0.03
B9: Employee Benefit Rate | C9: 0.3
E12: MANUFACTURING OVERHEAD & LOCATION ANALYSIS
E13: Warehouse Size (SQFT) YoY Growth Rate | F13: 0.01
B14: DIRECT MATERIALS | E14: Office Space (% of Total Warehouse Size) | F14: 0.05
B15: Inflation Rate | C15: 0.03 | E15: Monthly Rental Cost per Squarefoot | F15: 0.92
B16: Increase in Orders per Year | C16: 2 | E16: Rent Cost per SQFT Growth (2%) | F16: 0.02
B17: Fixed Cost per Order | C17: 40 | D17: Service Level Sensitivity | E17: Water Cost per Gallon | F17: 0.00305
B18: Target Service Level (Years 1 - 5) | C18: =95%*D18 -> 0.95 | D18: 1 | E18: Electicity Cost per KwH | F18: 0.14
B19: Service Level Z-Score (Years 1 - 5) | C19: =NORMINV(C18, 0, 1) -> 1.6448536 | E19: KwH Cost Growth Rate | F19: 0.02
B20: Holding Cost Rate | C20: 0.3
E21: Water Cost Per Gallon Growth Rate | F21: 0.02
E22: Gallons Used Per Year Growth Rate | F22: 0.05
B23: CAPITAL EXPENDITURES | E23: Service Cost per SQFT | F23: 30
B24: Finished Units per Industrial Shelf | C24: 9000 | E24: Inbound Freight Cost (% of Unit Cost) | F24: 0.1
E25: Indirect Materials (% of Direct Materials) | F25: 0.2289155
E26: Weight per Unit (incl. packaging) (lbs) | F26: 0.75
E27: Units per Pack | F27: 40
E28: Weight per Pack (lbs) | F28: =F26*F27 -> 30
E29: Case Cost per Pound | F29: 0.45
E30: Cost per 40 Unit Box (Independent Stores) | F30: =F29*F28 -> 13.5
E31: LTL Freight Cost per Pallet | F31: 246
B32: Finished Units per Wood Pallet | C32: 2000 | E32: Outbound Freight Rate Growth | F32: 0.02
